Workbook

Sheet PARÂMETROS
D1: Parâmetros de Composição de Valores [⚠ USO RESTRITO DO DPTO DE COMPRAS]
A3: COD. | C3: Marca | D3: Grupos | E3: Descrição do Grupo | F3: Percentual de Frete (%) | G3: Multiplicador Varejo | H3: Multiplicador Atacado | I3: Data de Atualização | K3: Fabricantes | M3: Categorias | O3: Grupos | Q3: Orçamentistas | R3: Vendedores
A4: =C4&D4 | C4: ALTEC | D4: A | E4: Rolos de Alumínio liso e corrugado | F4: 0.08 | G4: 2.12 | H4: 1.92 | I4: 45701 | K4: - | M4: - | O4: - | Q4: - | R4: -
A5: =C5&D5 | C5: ALTEC | D5: B | E5: Demais itens (exceto descrito nos demais grupos) | F5: 0.08 | G5: 2.12 | H5: 1.92 | I5: 45701 | K5: ALTEC | M5: VAREJO | O5: A | Q5: Arthur Maciel | R5: Luan Araújo
A6: =C6&D6 | C6: ALTEC | D6: C | K6: ARMACELL | M6: ATACADO | O6: B | Q6: Matheus Ramos | R6: Wellison Chaves
A7: =C7&D7 | C7: ALTEC | D7: D | K7: GENEBRE | O7: C | Q7: Lucas Aquino | R7: Bruno Crispim
A8: =C8&D8 | C8: ARMACELL | D8: A | E8: Todos os itens | F8: 0 | G8: 2.12 | H8: 1.92 | I8: 45701 | K8: GS.BOGADO | O8: D | R8: Túlio Batista
A9: =C9&D9 | C9: ARMACELL | D9: B | K9: IMI | R9: Rutemar Júnior
A10: =C10&D10 | C10: ARMACELL | D10: C | K10: ISOPUR | R10: Iago Rangel
A11: =C11&D11 | C11: ARMACELL | D11: D | K11: ISOVER | R11: Marlon Souza
A12: =C12&D12 | C12: GENEBRE | D12: A | E12: Todos os itens | F12: 0.08 | G12: 2.12 | H12: 1.92 | I12: 45701 | K12: MPU | R12: Ananda Araújo
A13: =C13&D13 | C13: GENEBRE | D13: B | K13: MULTIVAC | R13: José Nascimento
A14: =C14&D14 | C14: GENEBRE | D14: C | K14: NORMA DIN | R14: Patrick Galletti
A15: =C15&D15 | C15: GENEBRE | D15: D | K15: POWERMATIC
A16: =C16&D16 | C16: GS.BOGADO | D16: A | E16: Todos os itens | F16: 0.1 | G16: 2.12 | H16: 1.92 | I16: 45701 | K16: COMPRA LOCAL
A17: =C17&D17 | C17: GS.BOGADO | D17: B | K17: ROCKFIBRAS
A18: =C18&D18 | C18: GS.BOGADO | D18: C | K18: SICTELL
A19: =C19&D19 | C19: GS.BOGADO | D19: D | K19: TECTAPE
A20: =C20&D20 | C20: IMI | D20: A | E20: Todos os itens (venda para Goiânia/GO) | F20: 0.08 | G20: 2.12 | H20: 1.92 | I20: 45701 | K20: TRON
A21: =C21&D21 | C21: IMI | D21: B | E21: Todos os itens (venda para Brasília/DF) | F21: 0.11 | G21: 2.12 | H21: 1.92 | I21: 45701 | K21: TROX
A22: =C22&D22 | C22: IMI | D22: C | K22: VENTISOL
A23: =C23&D23 | C23: IMI | D23: D | K23: PENNSE
A24: =C24&D24 | C24: ISOPUR | D24: A | E24: Mantas | F24: 0.3 | G24: 2.12 | H24: 1.92 | I24: 45701 | K24: TRANE
A25: =C25&D25 | C25: ISOPUR | D25: B | E25: Demais itens (exceto descrito nos demais grupos) | F25: 0.1 | G25: 2.12 | H25: 1.92 | I25: 45701 | K25: ELECON/WALSYWA
A26: =C26&D26 | C26: ISOPUR | D26: C | K26: FORNECEDOR PVC-U
A27: =C27&D27 | C27: ISOPUR | D27: D | K27: PROJELMEC
A28: =C28&D28 | C28: ISOVER | D28: A | E28: Rolo de Manta | F28: 0.3 | G28: 2.12 | H28: 1.92 | I28: 45701 | K28: DAIKIN
A29: =C29&D29 | C29: ISOVER | D29: B | E29: Painel | F29: 0.5 | G29: 2.12 | H29: 1.92 | I29: 45701 | K29: FORNECEDOR DE COBRE
A30: =C30&D30 | C30: ISOVER | D30: C | E30: Demais itens (exceto descrito nos demais grupos) | F30: 0.1 | G30: 2.12 | H30: 1.92 | I30: 45701 | K30: ROCKTEC
A31: =C31&D31 | C31: ISOVER | D31: D | K31: -
A32: =C32&D32 | C32: MPU | D32: A | E32: Todos os itens | F32: 0.08 | G32: 2.12 | H32: 1.92 | I32: 45701 | K32: -
A33: =C33&D33 | C33: MPU | D33: B | K33: -
A34: =C34&D34 | C34: MPU | D34: C | K34: -
A35: =C35&D35 | C35: MPU | D35: D | K35: -
A36: =C36&D36 | C36: MULTIVAC | D36: A | E36: Todos os itens | F36: 0.08 | G36: 2.12 | H36: 1.92 | I36: 45701 | K36: -
A37: =C37&D37 | C37: MULTIVAC | D37: B | K37: -
A38: =C38&D38 | C38: MULTIVAC | D38: C | K38: -
A39: =C39&D39 | C39: MULTIVAC | D39: D | K39: -
A40: =C40&D40 | C40: NORMA DIN | D40: A | E40: Todos os itens | F40: 0.05 | G40: 2.12 | H40: 1.92 | I40: 45701 | K40: -
A41: =C41&D41 | C41: NORMA DIN | D41: B | K41: -
...

Sheet COMPOSIÇÃO DE VALORES
D1: =CONCATENATE("CTD ",C5," - Rev.: ",C6," - Composição de Valores - ",C8," - ",C4)
A3: Orçamentista: | C3: Luiz Henrique | H3: Categoria | K3: Data da última atualização de valores:
A4: Vendedor(a): | C4: Iago Rangel | H4: ATACADO
A5: Nº CTD: | C5: 1113 | K5: =AK11
A6: Revisão:
A8: Fabricante: | C8: TROX
A10: ITEM | B10: QTDE | C10: Unidade | D10: Descrição | E10: Grupo | F10: Descrição do Grupo | G10: Código (SKU) | H10: NCM | I10: Preço de Compra | J10: ST | K10: IPI | L10: =_xlfn.CONCAT("Preço de Venda: ",H4) | M10: Observações | AD10: MARCA | AE10: GRUPOS | AF10: COD. | AG10: DESCRIÇÃO DO GRUPO | AH10: PERCENTUAL DE FRETE | AI10: MULTIPLICADOR VAREJO | AJ10: MULTIPLICADOR ATACADO | AK10: DATA DE ATUALIZAÇÃO | AN10: ITEM | AO10: PREÇO DE COMPRA + ST + IPI | AP10: FRETE | AQ10: VALOR FRETE | AR10: PREÇO DE COMPRA + ST + IPI + FRETE | AT10: MULTIPLICADOR VAREJO | AU10: MULTIPLICADOR ATACADO | AW10: FT 1,0 (VAREJO) | AX10: FT 1,0 (ATACADO)
A11: 1 | B11: 8 | C11: PÇ | D11: 010 DAMPER RG-B 480x405 TROX | E11: C | F11: =IFERROR((VLOOKUP(E11,$AE$11:$AG$14,3,0)),"-") | G11: RG-B-480x405/D/0/00/000 | H11: 90261029 | I11: 176.23 | J11: 0 | K11: 0 | L11: =IF($H$4="-",0,IF($H$4="VAREJO",AW11,IF($H$4="ATACADO",AX11,0))) | AD11: =$C$8 | AE11: A | AF11: =AD11&AE11 | AG11: =IFERROR((VLOOKUP(AF11,PARÂMETROS!$A$4:$I$403,5,0)),0) | AH11: =IFERROR((VLOOKUP(AF11,PARÂMETROS!$A$4:$I$403,6,0)),0) | AI11: =IFERROR((VLOOKUP(AF11,PARÂMETROS!$A$4:$I$403,7,0)),0) | AJ11: =IFERROR((VLOOKUP(AF11,PARÂMETROS!$A$4:$I$403,8,0)),0) | AK11: =IFERROR((VLOOKUP(AF11,PARÂMETROS!$A$4:$I$403,9,0)),0) | AN11: 1 | AO11: =I11+(I11*J11)+(I11*K11) | AP11: =IFERROR(VLOOKUP(E11,$AE$11:$AK$14,4,0),0) | AQ11: =(I11+(I11*J11)+(I11*K11))*AP11 | AR11: =AO11+AQ11 | AT11: =IFERROR((VLOOKUP(E11,$AE$11:$AJ$14,5,0)),0) | AU11: =IFERROR((VLOOKUP(E11,$AE$11:$AJ$14,6,0)),0) | AW11: =AR11*AT11 | AX11: =AR11*AU11
A12: 2 | B12: 8 | C12: PÇ | D12: 010 DAMPER JN-B 0 800x800 00 000 TROX | E12: C | F12: =IFERROR((VLOOKUP(E12,$AE$11:$AG$14,3,0)),"-") | G12: JN-B-0-D-N0/800x800/N/00/000 | H12: 90261029 | I12: 770.28 | J12: 0 | K12: 0 | L12: =IF($H$4="-",0,IF($H$4="VAREJO",AW12,IF($H$4="ATACADO",AX12,0))) | AD12: =$C$8 | AE12: B | AF12: =AD12&AE12 | AG12: =IFERROR((VLOOKUP(AF12,PARÂMETROS!$A$4:$I$403,5,0)),0) | AH12: =IFERROR((VLOOKUP(AF12,PARÂMETROS!$A$4:$I$403,6,0)),0) | AI12: =VLOOKUP(AF12,PARÂMETROS!$A$4:$I$403,7,0) | AJ12: =IFERROR((VLOOKUP(AF12,PARÂMETROS!$A$4:$I$403,8,0)),0) | AK12: =IFERROR((VLOOKUP(AF12,PARÂMETROS!$A$4:$I$403,9,0)),0) | AN12: 2 | AO12: =I12+(I12*J12)+(I12*K12) | AP12: =IFERROR(VLOOKUP(E12,$AE$11:$AK$14,4,0),0) | AQ12: =(I12+(I12*J12)+(I12*K12))*AP12 | AR12: =AO12+AQ12 | AT12: =IFERROR((VLOOKUP(E12,$AE$11:$AJ$14,5,0)),0) | AU12: =IFERROR((VLOOKUP(E12,$AE$11:$AJ$14,6,0)),0) | AW12: =AR12*AT12 | AX12: =AR12*AU12
A13: 3 | B13: 1 | C13: PÇ | D13: 010 DAMPER JN-B 0 850x500 00 000 TROX | E13: C | F13: =IFERROR((VLOOKUP(E13,$AE$11:$AG$14,3,0)),"-") | G13: JN-B-0-D-N0/850x500/N/00/000 | H13: 90261029 | I13: 552.9 | J13: 0 | K13: 0 | L13: =IF($H$4="-",0,IF($H$4="VAREJO",AW13,IF($H$4="ATACADO",AX13,0))) | AD13: =$C$8 | AE13: C | AF13: =AD13&AE13 | AG13: =IFERROR((VLOOKUP(AF13,PARÂMETROS!$A$4:$I$403,5,0)),0) | AH13: =IFERROR((VLOOKUP(AF13,PARÂMETROS!$A$4:$I$403,6,0)),0) | AI13: =VLOOKUP(AF13,PARÂMETROS!$A$4:$I$403,7,0) | AJ13: =IFERROR((VLOOKUP(AF13,PARÂMETROS!$A$4:$I$403,8,0)),0) | AK13: =IFERROR((VLOOKUP(AF13,PARÂMETROS!$A$4:$I$403,9,0)),0) | AN13: 3 | AO13: =I13+(I13*J13)+(I13*K13) | AP13: =IFERROR(VLOOKUP(E13,$AE$11:$AK$14,4,0),0) | AQ13: =(I13+(I13*J13)+(I13*K13))*AP13 | AR13: =AO13+AQ13 | AT13: =IFERROR((VLOOKUP(E13,$AE$11:$AJ$14,5,0)),0) | AU13: =IFERROR((VLOOKUP(E13,$AE$11:$AJ$14,6,0)),0) | AW13: =AR13*AT13 | AX13: =AR13*AU13
A14: 4 | B14: 2 | C14: PÇ | D14: 010 DAMPER JN-B 0 1200x600 00 000 TROX | E14: C | F14: =IFERROR((VLOOKUP(E14,$AE$11:$AG$14,3,0)),"-") | G14: JN-B-0-D-N0/1200x600/N/00/000 | H14: 90261029 | I14: 758.47 | J14: 0 | K14: 0 | L14: =IF($H$4="-",0,IF($H$4="VAREJO",AW14,IF($H$4="ATACADO",AX14,0))) | AD14: =$C$8 | AE14: D | AF14: =AD14&AE14 | AG14: =IFERROR((VLOOKUP(AF14,PARÂMETROS!$A$4:$I$403,5,0)),0) | AH14: =IFERROR((VLOOKUP(AF14,PARÂMETROS!$A$4:$I$403,6,0)),0) | AI14: =VLOOKUP(AF14,PARÂMETROS!$A$4:$I$403,7,0) | AJ14: =IFERROR((VLOOKUP(AF14,PARÂMETROS!$A$4:$I$403,8,0)),0) | AK14: =IFERROR((VLOOKUP(AF14,PARÂMETROS!$A$4:$I$403,9,0)),0) | AN14: 4 | AO14: =I14+(I14*J14)+(I14*K14) | AP14: =IFERROR(VLOOKUP(E14,$AE$11:$AK$14,4,0),0) | AQ14: =(I14+(I14*J14)+(I14*K14))*AP14 | AR14: =AO14+AQ14 | AT14: =IFERROR((VLOOKUP(E14,$AE$11:$AJ$14,5,0)),0) | AU14: =IFERROR((VLOOKUP(E14,$AE$11:$AJ$14,6,0)),0) | AW14: =AR14*AT14 | AX14: =AR14*AU14
A15: 5 | B15: 1 | C15: PÇ | D15: 010 DAMPER JN-B 0 1800x400 00 000 TROX | E15: C | F15: =IFERROR((VLOOKUP(E15,$AE$11:$AG$14,3,0)),"-") | G15: JN-B-0-D-N0/1800x400/N/00/000 | H15: 90261029 | I15: 742.95 | J15: 0 | K15: 0 | L15: =IF($H$4="-",0,IF($H$4="VAREJO",AW15,IF($H$4="ATACADO",AX15,0))) | AN15: 5 | AO15: =I15+(I15*J15)+(I15*K15) | AP15: =IFERROR(VLOOKUP(E15,$AE$11:$AK$14,4,0),0) | AQ15: =(I15+(I15*J15)+(I15*K15))*AP15 | AR15: =AO15+AQ15 | AT15: =IFERROR((VLOOKUP(E15,$AE$11:$AJ$14,5,0)),0) | AU15: =IFERROR((VLOOKUP(E15,$AE$11:$AJ$14,6,0)),0) | AW15: =AR15*AT15 | AX15: =AR15*AU15
A16: 6 | B16: 418 | C16: PÇ | D16: 010 DIFUSOR ADLR T1 A PP5 TROX | E16: C | F16: =IFERROR((VLOOKUP(E16,$AE$11:$AG$14,3,0)),"-") | G16: ADLR-A-000-0/T1/0/PP5 | H16: 76169900 | I16: 105.04 | J16: 0 | K16: 0.0325 | L16: =IF($H$4="-",0,IF($H$4="VAREJO",AW16,IF($H$4="ATACADO",AX16,0))) | AN16: 6 | AO16: =I16+(I16*J16)+(I16*K16) | AP16: =IFERROR(VLOOKUP(E16,$AE$11:$AK$14,4,0),0) | AQ16: =(I16+(I16*J16)+(I16*K16))*AP16 | AR16: =AO16+AQ16 | AT16: =IFERROR((VLOOKUP(E16,$AE$11:$AJ$14,5,0)),0) | AU16: =IFERROR((VLOOKUP(E16,$AE$11:$AJ$14,6,0)),0) | AW16: =AR16*AT16 | AX16: =AR16*AU16
A17: 7 | E17: - | F17: =IFERROR((VLOOKUP(E17,$AE$11:$AG$14,3,0)),"-") | L17: =IF($H$4="-",0,IF($H$4="VAREJO",AW17,IF($H$4="ATACADO",AX17,0))) | AN17: 7 | AO17: =I17+(I17*J17)+(I17*K17) | AP17: =IFERROR(VLOOKUP(E17,$AE$11:$AK$14,4,0),0) | AQ17: =(I17+(I17*J17)+(I17*K17))*AP17 | AR17: =AO17+AQ17 | AT17: =IFERROR((VLOOKUP(E17,$AE$11:$AJ$14,5,0)),0) | AU17: =IFERROR((VLOOKUP(E17,$AE$11:$AJ$14,6,0)),0) | AW17: =AR17*AT17 | AX17: =AR17*AU17
A18: 8 | E18: - | F18: =IFERROR((VLOOKUP(E18,$AE$11:$AG$14,3,0)),"-") | L18: =IF($H$4="-",0,IF($H$4="VAREJO",AW18,IF($H$4="ATACADO",AX18,0))) | AN18: 8 | AO18: =I18+(I18*J18)+(I18*K18) | AP18: =IFERROR(VLOOKUP(E18,$AE$11:$AK$14,4,0),0) | AQ18: =(I18+(I18*J18)+(I18*K18))*AP18 | AR18: =AO18+AQ18 | AT18: =IFERROR((VLOOKUP(E18,$AE$11:$AJ$14,5,0)),0) | AU18: =IFERROR((VLOOKUP(E18,$AE$11:$AJ$14,6,0)),0) | AW18: =AR18*AT18 | AX18: =AR18*AU18
A19: 9 | E19: - | F19: =IFERROR((VLOOKUP(E19,$AE$11:$AG$14,3,0)),"-") | L19: =IF($H$4="-",0,IF($H$4="VAREJO",AW19,IF($H$4="ATACADO",AX19,0))) | AN19: 9 | AO19: =I19+(I19*J19)+(I19*K19) | AP19: =IFERROR(VLOOKUP(E19,$AE$11:$AK$14,4,0),0) | AQ19: =(I19+(I19*J19)+(I19*K19))*AP19 | AR19: =AO19+AQ19 | AT19: =IFERROR((VLOOKUP(E19,$AE$11:$AJ$14,5,0)),0) | AU19: =IFERROR((VLOOKUP(E19,$AE$11:$AJ$14,6,0)),0) | AW19: =AR19*AT19 | AX19: =AR19*AU19
A20: 10 | E20: - | F20: =IFERROR((VLOOKUP(E20,$AE$11:$AG$14,3,0)),"-") | L20: =IF($H$4="-",0,IF($H$4="VAREJO",AW20,IF($H$4="ATACADO",AX20,0))) | AN20: 10 | AO20: =I20+(I20*J20)+(I20*K20) | AP20: =IFERROR(VLOOKUP(E20,$AE$11:$AK$14,4,0),0) | AQ20: =(I20+(I20*J20)+(I20*K20))*AP20 | AR20: =AO20+AQ20 | AT20: =IFERROR((VLOOKUP(E20,$AE$11:$AJ$14,5,0)),0) | AU20: =IFERROR((VLOOKUP(E20,$AE$11:$AJ$14,6,0)),0) | AW20: =AR20*AT20 | AX20: =AR20*AU20
A21: 11 | E21: - | F21: =IFERROR((VLOOKUP(E21,$AE$11:$AG$14,3,0)),"-") | L21: =IF($H$4="-",0,IF($H$4="VAREJO",AW21,IF($H$4="ATACADO",AX21,0))) | AN21: 11 | AO21: =I21+(I21*J21)+(I21*K21) | AP21: =IFERROR(VLOOKUP(E21,$AE$11:$AK$14,4,0),0) | AQ21: =(I21+(I21*J21)+(I21*K21))*AP21 | AR21: =AO21+AQ21 | AT21: =IFERROR((VLOOKUP(E21,$AE$11:$AJ$14,5,0)),0) | AU21: =IFERROR((VLOOKUP(E21,$AE$11:$AJ$14,6,0)),0) | AW21: =AR21*AT21 | AX21: =AR21*AU21
A22: 12 | E22: - | F22: =IFERROR((VLOOKUP(E22,$AE$11:$AG$14,3,0)),"-") | L22: =IF($H$4="-",0,IF($H$4="VAREJO",AW22,IF($H$4="ATACADO",AX22,0))) | AN22: 12 | AO22: =I22+(I22*J22)+(I22*K22) | AP22: =IFERROR(VLOOKUP(E22,$AE$11:$AK$14,4,0),0) | AQ22: =(I22+(I22*J22)+(I22*K22))*AP22 | AR22: =AO22+AQ22 | AT22: =IFERROR((VLOOKUP(E22,$AE$11:$AJ$14,5,0)),0) | AU22: =IFERROR((VLOOKUP(E22,$AE$11:$AJ$14,6,0)),0) | AW22: =AR22*AT22 | AX22: =AR22*AU22
A23: 13 | E23: - | F23: =IFERROR((VLOOKUP(E23,$AE$11:$AG$14,3,0)),"-") | L23: =IF($H$4="-",0,IF($H$4="VAREJO",AW23,IF($H$4="ATACADO",AX23,0))) | AN23: 13 | AO23: =I23+(I23*J23)+(I23*K23) | AP23: =IFERROR(VLOOKUP(E23,$AE$11:$AK$14,4,0),0) | AQ23: =(I23+(I23*J23)+(I23*K23))*AP23 | AR23: =AO23+AQ23 | AT23: =IFERROR((VLOOKUP(E23,$AE$11:$AJ$14,5,0)),0) | AU23: =IFERROR((VLOOKUP(E23,$AE$11:$AJ$14,6,0)),0) | AW23: =AR23*AT23 | AX23: =AR23*AU23
A24: 14 | E24: - | F24: =IFERROR((VLOOKUP(E24,$AE$11:$AG$14,3,0)),"-") | L24: =IF($H$4="-",0,IF($H$4="VAREJO",AW24,IF($H$4="ATACADO",AX24,0))) | AN24: 14 | AO24: =I24+(I24*J24)+(I24*K24) | AP24: =IFERROR(VLOOKUP(E24,$AE$11:$AK$14,4,0),0) | AQ24: =(I24+(I24*J24)+(I24*K24))*AP24 | AR24: =AO24+AQ24 | AT24: =IFERROR((VLOOKUP(E24,$AE$11:$AJ$14,5,0)),0) | AU24: =IFERROR((VLOOKUP(E24,$AE$11:$AJ$14,6,0)),0) | AW24: =AR24*AT24 | AX24: =AR24*AU24
A25: 15 | E25: - | F25: =IFERROR((VLOOKUP(E25,$AE$11:$AG$14,3,0)),"-") | L25: =IF($H$4="-",0,IF($H$4="VAREJO",AW25,IF($H$4="ATACADO",AX25,0))) | AN25: 15 | AO25: =I25+(I25*J25)+(I25*K25) | AP25: =IFERROR(VLOOKUP(E25,$AE$11:$AK$14,4,0),0) | AQ25: =(I25+(I25*J25)+(I25*K25))*AP25 | AR25: =AO25+AQ25 | AT25: =IFERROR((VLOOKUP(E25,$AE$11:$AJ$14,5,0)),0) | AU25: =IFERROR((VLOOKUP(E25,$AE$11:$AJ$14,6,0)),0) | AW25: =AR25*AT25 | AX25: =AR25*AU25
A26: 16 | E26: - | F26: =IFERROR((VLOOKUP(E26,$AE$11:$AG$14,3,0)),"-") | L26: =IF($H$4="-",0,IF($H$4="VAREJO",AW26,IF($H$4="ATACADO",AX26,0))) | AN26: 16 | AO26: =I26+(I26*J26)+(I26*K26) | AP26: =IFERROR(VLOOKUP(E26,$AE$11:$AK$14,4,0),0) | AQ26: =(I26+(I26*J26)+(I26*K26))*AP26 | AR26: =AO26+AQ26 | AT26: =IFERROR((VLOOKUP(E26,$AE$11:$AJ$14,5,0)),0) | AU26: =IFERROR((VLOOKUP(E26,$AE$11:$AJ$14,6,0)),0) | AW26: =AR26*AT26 | AX26: =AR26*AU26
A27: 17 | E27: - | F27: =IFERROR((VLOOKUP(E27,$AE$11:$AG$14,3,0)),"-") | L27: =IF($H$4="-",0,IF($H$4="VAREJO",AW27,IF($H$4="ATACADO",AX27,0))) | AN27: 17 | AO27: =I27+(I27*J27)+(I27*K27) | AP27: =IFERROR(VLOOKUP(E27,$AE$11:$AK$14,4,0),0) | AQ27: =(I27+(I27*J27)+(I27*K27))*AP27 | AR27: =AO27+AQ27 | AT27: =IFERROR((VLOOKUP(E27,$AE$11:$AJ$14,5,0)),0) | AU27: =IFERROR((VLOOKUP(E27,$AE$11:$AJ$14,6,0)),0) | AW27: =AR27*AT27 | AX27: =AR27*AU27
A28: 18 | E28: - | F28: =IFERROR((VLOOKUP(E28,$AE$11:$AG$14,3,0)),"-") | L28: =IF($H$4="-",0,IF($H$4="VAREJO",AW28,IF($H$4="ATACADO",AX28,0))) | AN28: 18 | AO28: =I28+(I28*J28)+(I28*K28) | AP28: =IFERROR(VLOOKUP(E28,$AE$11:$AK$14,4,0),0) | AQ28: =(I28+(I28*J28)+(I28*K28))*AP28 | AR28: =AO28+AQ28 | AT28: =IFERROR((VLOOKUP(E28,$AE$11:$AJ$14,5,0)),0) | AU28: =IFERROR((VLOOKUP(E28,$AE$11:$AJ$14,6,0)),0) | AW28: =AR28*AT28 | AX28: =AR28*AU28
... A510: 500 | E510: - | F510: =IFERROR((VLOOKUP(E510,$AE$11:$AG$14,3,0)),"-") | L510: =IF($H$4="-",0,IF($H$4="VAREJO",AW510,IF($H$4="ATACADO",AX510,0))) | AN510: 500 | AO510: =I510+(I510*J510)+(I510*K510) | AP510: =IFERROR(VLOOKUP(E510,$AE$11:$AK$14,4,0),0) | AQ510: =(I510+(I510*J510)+(I510*K510))*AP510 | AR510: =AO510+AQ510 | AT510: =IFERROR((VLOOKUP(E510,$AE$11:$AJ$14,5,0)),0) | AU510: =IFERROR((VLOOKUP(E510,$AE$11:$AJ$14,6,0)),0) | AW510: =AR510*AT510 | AX510: =AR510*AU510

Sheet RELATÓRIO
C1: =CONCATENATE("CTD ",C5," - Rev. ",C6," - ",C8," - ",C4)
A3: Orçamentista: | C3: ='COMPOSIÇÃO DE VALORES'!C3 | F3: Categoria | I3: Soma Total
A4: Vendedor(a): | C4: ='COMPOSIÇÃO DE VALORES'!C4 | F4: =W4 | I4: =SUM(H11:H5000) | W4: {='COMPOSIÇÃO DE VALORES'!H4:I4} | X4: 0
A5: Nº CTD: | C5: ='COMPOSIÇÃO DE VALORES'!C5
A6: Revisão: | C6: ='COMPOSIÇÃO DE VALORES'!C6
A8: Fabricante: | C8: ='COMPOSIÇÃO DE VALORES'!C8
A10: Item | B10: Qtde | C10: Unidade | D10: Descrição | E10: Código (SKU) | F10: NCM | G10: =_xlfn.CONCAT("Preço de Venda (Unitário): ",F4) | H10: =_xlfn.CONCAT("Preço de Venda (Soma): ",F4) | I10: Observações
A11: 1 | B11: ='COMPOSIÇÃO DE VALORES'!B11 | C11: ='COMPOSIÇÃO DE VALORES'!C11 | D11: ='COMPOSIÇÃO DE VALORES'!D11 | E11: ='COMPOSIÇÃO DE VALORES'!G11 | F11: ='COMPOSIÇÃO DE VALORES'!H11 | G11: ='COMPOSIÇÃO DE VALORES'!L11 | H11: =G11*B11 | I11: =IF(('COMPOSIÇÃO DE VALORES'!M11)=0,"-",('COMPOSIÇÃO DE VALORES'!M11))
A12: 2 | B12: ='COMPOSIÇÃO DE VALORES'!B12 | C12: ='COMPOSIÇÃO DE VALORES'!C12 | D12: ='COMPOSIÇÃO DE VALORES'!D12 | E12: ='COMPOSIÇÃO DE VALORES'!G12 | F12: ='COMPOSIÇÃO DE VALORES'!H12 | G12: ='COMPOSIÇÃO DE VALORES'!L12 | H12: =G12*B12 | I12: =IF(('COMPOSIÇÃO DE VALORES'!M12)=0,"-",('COMPOSIÇÃO DE VALORES'!M12))
A13: 3 | B13: ='COMPOSIÇÃO DE VALORES'!B13 | C13: ='COMPOSIÇÃO DE VALORES'!C13 | D13: ='COMPOSIÇÃO DE VALORES'!D13 | E13: ='COMPOSIÇÃO DE VALORES'!G13 | F13: ='COMPOSIÇÃO DE VALORES'!H13 | G13: ='COMPOSIÇÃO DE VALORES'!L13 | H13: =G13*B13 | I13: =IF(('COMPOSIÇÃO DE VALORES'!M13)=0,"-",('COMPOSIÇÃO DE VALORES'!M13))
A14: 4 | B14: ='COMPOSIÇÃO DE VALORES'!B14 | C14: ='COMPOSIÇÃO DE VALORES'!C14 | D14: ='COMPOSIÇÃO DE VALORES'!D14 | E14: ='COMPOSIÇÃO DE VALORES'!G14 | F14: ='COMPOSIÇÃO DE VALORES'!H14 | G14: ='COMPOSIÇÃO DE VALORES'!L14 | H14: =G14*B14 | I14: =IF(('COMPOSIÇÃO DE VALORES'!M14)=0,"-",('COMPOSIÇÃO DE VALORES'!M14))
A15: 5 | B15: ='COMPOSIÇÃO DE VALORES'!B15 | C15: ='COMPOSIÇÃO DE VALORES'!C15 | D15: ='COMPOSIÇÃO DE VALORES'!D15 | E15: ='COMPOSIÇÃO DE VALORES'!G15 | F15: ='COMPOSIÇÃO DE VALORES'!H15 | G15: ='COMPOSIÇÃO DE VALORES'!L15 | H15: =G15*B15 | I15: =IF(('COMPOSIÇÃO DE VALORES'!M15)=0,"-",('COMPOSIÇÃO DE VALORES'!M15))
A16: 6 | B16: ='COMPOSIÇÃO DE VALORES'!B16 | C16: ='COMPOSIÇÃO DE VALORES'!C16 | D16: ='COMPOSIÇÃO DE VALORES'!D16 | E16: ='COMPOSIÇÃO DE VALORES'!G16 | F16: ='COMPOSIÇÃO DE VALORES'!H16 | G16: ='COMPOSIÇÃO DE VALORES'!L16 | H16: =G16*B16 | I16: =IF(('COMPOSIÇÃO DE VALORES'!M16)=0,"-",('COMPOSIÇÃO DE VALORES'!M16))
A17: 7 | B17: ='COMPOSIÇÃO DE VALORES'!B17 | C17: ='COMPOSIÇÃO DE VALORES'!C17 | D17: ='COMPOSIÇÃO DE VALORES'!D17 | E17: ='COMPOSIÇÃO DE VALORES'!G17 | F17: ='COMPOSIÇÃO DE VALORES'!H17 | G17: ='COMPOSIÇÃO DE VALORES'!L17 | H17: =G17*B17 | I17: =IF(('COMPOSIÇÃO DE VALORES'!M17)=0,"-",('COMPOSIÇÃO DE VALORES'!M17))
A18: 8 | B18: ='COMPOSIÇÃO DE VALORES'!B18 | C18: ='COMPOSIÇÃO DE VALORES'!C18 | D18: ='COMPOSIÇÃO DE VALORES'!D18 | E18: ='COMPOSIÇÃO DE VALORES'!G18 | F18: ='COMPOSIÇÃO DE VALORES'!H18 | G18: ='COMPOSIÇÃO DE VALORES'!L18 | H18: =G18*B18 | I18: =IF(('COMPOSIÇÃO DE VALORES'!M18)=0,"-",('COMPOSIÇÃO DE VALORES'!M18))
A19: 9 | B19: ='COMPOSIÇÃO DE VALORES'!B19 | C19: ='COMPOSIÇÃO DE VALORES'!C19 | D19: ='COMPOSIÇÃO DE VALORES'!D19 | E19: ='COMPOSIÇÃO DE VALORES'!G19 | F19: ='COMPOSIÇÃO DE VALORES'!H19 | G19: ='COMPOSIÇÃO DE VALORES'!L19 | H19: =G19*B19 | I19: =IF(('COMPOSIÇÃO DE VALORES'!M19)=0,"-",('COMPOSIÇÃO DE VALORES'!M19))
A20: 10 | B20: ='COMPOSIÇÃO DE VALORES'!B20 | C20: ='COMPOSIÇÃO DE VALORES'!C20 | D20: ='COMPOSIÇÃO DE VALORES'!D20 | E20: ='COMPOSIÇÃO DE VALORES'!G20 | F20: ='COMPOSIÇÃO DE VALORES'!H20 | G20: ='COMPOSIÇÃO DE VALORES'!L20 | H20: =G20*B20 | I20: =IF(('COMPOSIÇÃO DE VALORES'!M20)=0,"-",('COMPOSIÇÃO DE VALORES'!M20))
A21: 11 | B21: ='COMPOSIÇÃO DE VALORES'!B21 | C21: ='COMPOSIÇÃO DE VALORES'!C21 | D21: ='COMPOSIÇÃO DE VALORES'!D21 | E21: ='COMPOSIÇÃO DE VALORES'!G21 | F21: ='COMPOSIÇÃO DE VALORES'!H21 | G21: ='COMPOSIÇÃO DE VALORES'!L21 | H21: =G21*B21 | I21: =IF(('COMPOSIÇÃO DE VALORES'!M21)=0,"-",('COMPOSIÇÃO DE VALORES'!M21))
A22: 12 | B22: ='COMPOSIÇÃO DE VALORES'!B22 | C22: ='COMPOSIÇÃO DE VALORES'!C22 | D22: ='COMPOSIÇÃO DE VALORES'!D22 | E22: ='COMPOSIÇÃO DE VALORES'!G22 | F22: ='COMPOSIÇÃO DE VALORES'!H22 | G22: ='COMPOSIÇÃO DE VALORES'!L22 | H22: =G22*B22 | I22: =IF(('COMPOSIÇÃO DE VALORES'!M22)=0,"-",('COMPOSIÇÃO DE VALORES'!M22))
... A510: 500 | B510: ='COMPOSIÇÃO DE VALORES'!B510 | C510: ='COMPOSIÇÃO DE VALORES'!C510 | D510: ='COMPOSIÇÃO DE VALORES'!D510 | E510: ='COMPOSIÇÃO DE VALORES'!G510 | F510: ='COMPOSIÇÃO DE VALORES'!H510 | G510: ='COMPOSIÇÃO DE VALORES'!L510 | H510: =G510*B510 | I510: =IF(('COMPOSIÇÃO DE VALORES'!M510)=0,"-",('COMPOSIÇÃO DE VALORES'!M510))
